{"trial_id": "1", "hyperparameters": {"space": [{"class_name": "Int", "config": {"name": "units", "default": null, "conditions": [], "min_value": 32, "max_value": 512, "step": 32, "sampling": "linear"}}, {"class_name": "Choice", "config": {"name": "learning_rate", "default": 0.01, "conditions": [], "values": [0.01, 0.001, 0.0001], "ordered": true}}], "values": {"units": 512, "learning_rate": 0.0001}}, "metrics": {"metrics": {}}, "score": null, "best_step": 0, "status": "FAILED", "message": "Traceback (most recent call last):\n  File \"/Users/nataliaacevedo/modelo_202312/.venv/lib/python3.11/site-packages/keras_tuner/src/engine/base_tuner.py\", line 274, in _try_run_and_update_trial\n    self._run_and_update_trial(trial, *fit_args, **fit_kwargs)\n  File \"/Users/nataliaacevedo/modelo_202312/.venv/lib/python3.11/site-packages/keras_tuner/src/engine/base_tuner.py\", line 239, in _run_and_update_trial\n    results = self.run_trial(trial, *fit_args, **fit_kwargs)\n              ^^^^^^^^^^^^^^^^^^^^^^^^^^^^^^^^^^^^^^^^^^^^^^\n  File \"/Users/nataliaacevedo/modelo_202312/.venv/lib/python3.11/site-packages/keras_tuner/src/engine/tuner.py\", line 314, in run_trial\n    obj_value = self._build_and_fit_model(trial, *args, **copied_kwargs)\n                ^^^^^^^^^^^^^^^^^^^^^^^^^^^^^^^^^^^^^^^^^^^^^^^^^^^^^^^^\n  File \"/Users/nataliaacevedo/modelo_202312/.venv/lib/python3.11/site-packages/keras_tuner/src/engine/tuner.py\", line 233, in _build_and_fit_model\n    results = self.hypermodel.fit(hp, model, *args, **kwargs)\n              ^^^^^^^^^^^^^^^^^^^^^^^^^^^^^^^^^^^^^^^^^^^^^^^\n  File \"/Users/nataliaacevedo/modelo_202312/.venv/lib/python3.11/site-packages/keras_tuner/src/engine/hypermodel.py\", line 149, in fit\n    return model.fit(*args, **kwargs)\n           ^^^^^^^^^^^^^^^^^^^^^^^^^^\n  File \"/Users/nataliaacevedo/modelo_202312/.venv/lib/python3.11/site-packages/keras/src/utils/traceback_utils.py\", line 70, in error_handler\n    raise e.with_traceback(filtered_tb) from None\n  File \"/Users/nataliaacevedo/modelo_202312/.venv/lib/python3.11/site-packages/tensorflow/python/eager/execute.py\", line 59, in quick_execute\n    except TypeError as e:\ntensorflow.python.framework.errors_impl.UnimplementedError: Graph execution error:\n\nDetected at node mean_squared_error/Cast defined at (most recent call last):\n  File \"/opt/homebrew/Cellar/python@3.11/3.11.6_1/Frameworks/Python.framework/Versions/3.11/lib/python3.11/runpy.py\", line 198, in _run_module_as_main\n\n  File \"/opt/homebrew/Cellar/python@3.11/3.11.6_1/Frameworks/Python.framework/Versions/3.11/lib/python3.11/runpy.py\", line 88, in _run_code\n\n  File \"/Users/nataliaacevedo/.vscode/extensions/ms-python.debugpy-2024.7.11591012/bundled/libs/debugpy/adapter/../../debugpy/launcher/../../debugpy/__main__.py\", line 39, in <module>\n\n  File \"/Users/nataliaacevedo/.vscode/extensions/ms-python.debugpy-2024.7.11591012/bundled/libs/debugpy/adapter/../../debugpy/launcher/../../debugpy/../debugpy/server/cli.py\", line 430, in main\n\n  File \"/Users/nataliaacevedo/.vscode/extensions/ms-python.debugpy-2024.7.11591012/bundled/libs/debugpy/adapter/../../debugpy/launcher/../../debugpy/../debugpy/server/cli.py\", line 284, in run_file\n\n  File \"/Users/nataliaacevedo/.vscode/extensions/ms-python.debugpy-2024.7.11591012/bundled/libs/debugpy/_vendored/pydevd/_pydevd_bundle/pydevd_runpy.py\", line 321, in run_path\n\n  File \"/Users/nataliaacevedo/.vscode/extensions/ms-python.debugpy-2024.7.11591012/bundled/libs/debugpy/_vendored/pydevd/_pydevd_bundle/pydevd_runpy.py\", line 135, in _run_module_code\n\n  File \"/Users/nataliaacevedo/.vscode/extensions/ms-python.debugpy-2024.7.11591012/bundled/libs/debugpy/_vendored/pydevd/_pydevd_bundle/pydevd_runpy.py\", line 124, in _run_code\n\n  File \"/Users/nataliaacevedo/modelo_202312/src/lstm_model.py\", line 71, in <module>\n\n  File \"/Users/nataliaacevedo/modelo_202312/src/lstm_model.py\", line 55, in lstm_model\n\n  File \"/Users/nataliaacevedo/modelo_202312/.venv/lib/python3.11/site-packages/keras_tuner/src/engine/base_tuner.py\", line 234, in search\n\n  File \"/Users/nataliaacevedo/modelo_202312/.venv/lib/python3.11/site-packages/keras_tuner/src/engine/base_tuner.py\", line 274, in _try_run_and_update_trial\n\n  File \"/Users/nataliaacevedo/modelo_202312/.venv/lib/python3.11/site-packages/keras_tuner/src/engine/base_tuner.py\", line 239, in _run_and_update_trial\n\n  File \"/Users/nataliaacevedo/modelo_202312/.venv/lib/python3.11/site-packages/keras_tuner/src/engine/tuner.py\", line 314, in run_trial\n\n  File \"/Users/nataliaacevedo/modelo_202312/.venv/lib/python3.11/site-packages/keras_tuner/src/engine/tuner.py\", line 233, in _build_and_fit_model\n\n  File \"/Users/nataliaacevedo/modelo_202312/.venv/lib/python3.11/site-packages/keras_tuner/src/engine/hypermodel.py\", line 149, in fit\n\n  File \"/Users/nataliaacevedo/modelo_202312/.venv/lib/python3.11/site-packages/keras/src/utils/traceback_utils.py\", line 65, in error_handler\n\n  File \"/Users/nataliaacevedo/modelo_202312/.venv/lib/python3.11/site-packages/keras/src/engine/training.py\", line 1807, in fit\n\n  File \"/Users/nataliaacevedo/modelo_202312/.venv/lib/python3.11/site-packages/keras/src/engine/training.py\", line 1401, in train_function\n\n  File \"/Users/nataliaacevedo/modelo_202312/.venv/lib/python3.11/site-packages/keras/src/engine/training.py\", line 1384, in step_function\n\n  File \"/Users/nataliaacevedo/modelo_202312/.venv/lib/python3.11/site-packages/keras/src/engine/training.py\", line 1373, in run_step\n\n  File \"/Users/nataliaacevedo/modelo_202312/.venv/lib/python3.11/site-packages/keras/src/engine/training.py\", line 1151, in train_step\n\n  File \"/Users/nataliaacevedo/modelo_202312/.venv/lib/python3.11/site-packages/keras/src/engine/training.py\", line 1209, in compute_loss\n\n  File \"/Users/nataliaacevedo/modelo_202312/.venv/lib/python3.11/site-packages/keras/src/engine/compile_utils.py\", line 277, in __call__\n\n  File \"/Users/nataliaacevedo/modelo_202312/.venv/lib/python3.11/site-packages/keras/src/losses.py\", line 143, in __call__\n\n  File \"/Users/nataliaacevedo/modelo_202312/.venv/lib/python3.11/site-packages/keras/src/losses.py\", line 270, in call\n\n  File \"/Users/nataliaacevedo/modelo_202312/.venv/lib/python3.11/site-packages/keras/src/losses.py\", line 1705, in mean_squared_error\n\nCast string to float is not supported\n\t [[{{node mean_squared_error/Cast}}]] [Op:__inference_train_function_6601]\n"}